[32m2024-04-12 12:11:06 +0000[0m - dagster - [34mDEBUG[0m - __ASSET_JOB - 467029b8-cc08-4f3a-98f9-91863582506d - 180136 - LOGS_CAPTURED - Started capturing logs in process (pid: 180136).
[32m2024-04-12 12:11:06 +0000[0m - dagster - [34mDEBUG[0m - __ASSET_JOB - 467029b8-cc08-4f3a-98f9-91863582506d - 180136 - player_roles - STEP_START - Started execution of step "player_roles".
[32m2024-04-12 12:11:26 +0000[0m - dagster - [34mERROR[0m - [31m__ASSET_JOB - 467029b8-cc08-4f3a-98f9-91863582506d - 180136 - player_roles - STEP_FAILURE - Execution of step "player_roles" failed.

dagster._core.errors.DagsterExecutionStepExecutionError: Error occurred while executing op "player_roles"::

requests.exceptions.ConnectionError: HTTPSConnectionPool(host='craftednba.com', port=443): Max retries exceeded with url: /players/austin-reaves (Caused by NewConnectionError('<urllib3.connection.HTTPSConnection object at 0x7f4525987210>: Failed to establish a new connection: [Errno -2] Name or service not known'))

Stack Trace:
  File "/home/gbemike/Documents/github/nba_pipeline/.venv/lib/python3.11/site-packages/dagster/_core/execution/plan/utils.py", line 54, in op_execution_error_boundary
    yield
  File "/home/gbemike/Documents/github/nba_pipeline/.venv/lib/python3.11/site-packages/dagster/_utils/__init__.py", line 463, in iterate_with_context
    next_output = next(iterator)
                  ^^^^^^^^^^^^^^
  File "/home/gbemike/Documents/github/nba_pipeline/.venv/lib/python3.11/site-packages/dagster/_core/execution/plan/compute_generator.py", line 131, in _coerce_op_compute_fn_to_iterator
    result = invoke_compute_fn(
             ^^^^^^^^^^^^^^^^^^
  File "/home/gbemike/Documents/github/nba_pipeline/.venv/lib/python3.11/site-packages/dagster/_core/execution/plan/compute_generator.py", line 125, in invoke_compute_fn
    return fn(context, **args_to_pass) if context_arg_provided else fn(**args_to_pass)
           ^^^^^^^^^^^^^^^^^^^^^^^^^^^
  File "/home/gbemike/Documents/github/nba_pipeline/nba_pipeline_dagster/nba_pipeline_dagster/assets.py", line 129, in player_roles
    response = requests.get(player_url)
               ^^^^^^^^^^^^^^^^^^^^^^^^
  File "/home/gbemike/Documents/github/nba_pipeline/.venv/lib/python3.11/site-packages/requests/api.py", line 73, in get
    return request("get", url, params=params, **kwargs)
           ^^^^^^^^^^^^^^^^^^^^^^^^^^^^^^^^^^^^^^^^^^^^
  File "/home/gbemike/Documents/github/nba_pipeline/.venv/lib/python3.11/site-packages/requests/api.py", line 59, in request
    return session.request(method=method, url=url, **kwargs)
           ^^^^^^^^^^^^^^^^^^^^^^^^^^^^^^^^^^^^^^^^^^^^^^^^^
  File "/home/gbemike/Documents/github/nba_pipeline/.venv/lib/python3.11/site-packages/requests/sessions.py", line 589, in request
    resp = self.send(prep, **send_kwargs)
           ^^^^^^^^^^^^^^^^^^^^^^^^^^^^^^
  File "/home/gbemike/Documents/github/nba_pipeline/.venv/lib/python3.11/site-packages/requests/sessions.py", line 703, in send
    r = adapter.send(request, **kwargs)
        ^^^^^^^^^^^^^^^^^^^^^^^^^^^^^^^
  File "/home/gbemike/Documents/github/nba_pipeline/.venv/lib/python3.11/site-packages/requests/adapters.py", line 519, in send
    raise ConnectionError(e, request=request)

The above exception occurred during handling of the following exception:
urllib3.exceptions.MaxRetryError: HTTPSConnectionPool(host='craftednba.com', port=443): Max retries exceeded with url: /players/austin-reaves (Caused by NewConnectionError('<urllib3.connection.HTTPSConnection object at 0x7f4525987210>: Failed to establish a new connection: [Errno -2] Name or service not known'))

Stack Trace:
  File "/home/gbemike/Documents/github/nba_pipeline/.venv/lib/python3.11/site-packages/requests/adapters.py", line 486, in send
    resp = conn.urlopen(
           ^^^^^^^^^^^^^
  File "/home/gbemike/Documents/github/nba_pipeline/.venv/lib/python3.11/site-packages/urllib3/connectionpool.py", line 799, in urlopen
    retries = retries.increment(
              ^^^^^^^^^^^^^^^^^^
  File "/home/gbemike/Documents/github/nba_pipeline/.venv/lib/python3.11/site-packages/urllib3/util/retry.py", line 592, in increment
    raise MaxRetryError(_pool, url, error or ResponseError(cause))

The above exception occurred during handling of the following exception:
urllib3.exceptions.NewConnectionError: <urllib3.connection.HTTPSConnection object at 0x7f4525987210>: Failed to establish a new connection: [Errno -2] Name or service not known

Stack Trace:
  File "/home/gbemike/Documents/github/nba_pipeline/.venv/lib/python3.11/site-packages/urllib3/connectionpool.py", line 715, in urlopen
    httplib_response = self._make_request(
                       ^^^^^^^^^^^^^^^^^^^
  File "/home/gbemike/Documents/github/nba_pipeline/.venv/lib/python3.11/site-packages/urllib3/connectionpool.py", line 404, in _make_request
    self._validate_conn(conn)
  File "/home/gbemike/Documents/github/nba_pipeline/.venv/lib/python3.11/site-packages/urllib3/connectionpool.py", line 1058, in _validate_conn
    conn.connect()
  File "/home/gbemike/Documents/github/nba_pipeline/.venv/lib/python3.11/site-packages/urllib3/connection.py", line 363, in connect
    self.sock = conn = self._new_conn()
                       ^^^^^^^^^^^^^^^^
  File "/home/gbemike/Documents/github/nba_pipeline/.venv/lib/python3.11/site-packages/urllib3/connection.py", line 186, in _new_conn
    raise NewConnectionError(

The above exception occurred during handling of the following exception:
socket.gaierror: [Errno -2] Name or service not known

Stack Trace:
  File "/home/gbemike/Documents/github/nba_pipeline/.venv/lib/python3.11/site-packages/urllib3/connection.py", line 174, in _new_conn
    conn = connection.create_connection(
           ^^^^^^^^^^^^^^^^^^^^^^^^^^^^^
  File "/home/gbemike/Documents/github/nba_pipeline/.venv/lib/python3.11/site-packages/urllib3/util/connection.py", line 72, in create_connection
    for res in socket.getaddrinfo(host, port, family, socket.SOCK_STREAM):
               ^^^^^^^^^^^^^^^^^^^^^^^^^^^^^^^^^^^^^^^^^^^^^^^^^^^^^^^^^^
  File "/home/gbemike/anaconda3/lib/python3.11/socket.py", line 962, in getaddrinfo
    for res in _socket.getaddrinfo(host, port, family, type, proto, flags):
               ^^^^^^^^^^^^^^^^^^^^^^^^^^^^^^^^^^^^^^^^^^^^^^^^^^^^^^^^^^^
[0m
