[32m2024-04-02 12:41:50 +0000[0m - dagster - [34mDEBUG[0m - __ASSET_JOB - 5597899e-5906-48c0-b047-0563e649175a - 558601 - LOGS_CAPTURED - Started capturing logs in process (pid: 558601).
[32m2024-04-02 12:41:50 +0000[0m - dagster - [34mDEBUG[0m - __ASSET_JOB - 5597899e-5906-48c0-b047-0563e649175a - 558601 - player_names - STEP_START - Started execution of step "player_names".
[32m2024-04-02 12:41:53 +0000[0m - dagster - [34mERROR[0m - [31m__ASSET_JOB - 5597899e-5906-48c0-b047-0563e649175a - 558601 - player_names - STEP_FAILURE - Execution of step "player_names" failed.

dagster._core.errors.DagsterExecutionStepExecutionError: Error occurred while executing op "player_names"::

KeyError: 'player_name'

Stack Trace:
  File "/home/gbemike/Documents/github/nba_pipeline/.venv/lib/python3.11/site-packages/dagster/_core/execution/plan/utils.py", line 54, in op_execution_error_boundary
    yield
  File "/home/gbemike/Documents/github/nba_pipeline/.venv/lib/python3.11/site-packages/dagster/_utils/__init__.py", line 463, in iterate_with_context
    next_output = next(iterator)
                  ^^^^^^^^^^^^^^
  File "/home/gbemike/Documents/github/nba_pipeline/.venv/lib/python3.11/site-packages/dagster/_core/execution/plan/compute_generator.py", line 131, in _coerce_op_compute_fn_to_iterator
    result = invoke_compute_fn(
             ^^^^^^^^^^^^^^^^^^
  File "/home/gbemike/Documents/github/nba_pipeline/.venv/lib/python3.11/site-packages/dagster/_core/execution/plan/compute_generator.py", line 125, in invoke_compute_fn
    return fn(context, **args_to_pass) if context_arg_provided else fn(**args_to_pass)
           ^^^^^^^^^^^^^^^^^^^^^^^^^^^
  File "/home/gbemike/Documents/github/nba_pipeline/nba_pipeline_dagster/nba_pipeline_dagster/assets.py", line 46, in player_names
    df['player_name'] = df['player_name'].str.replace("'","")
                        ~~^^^^^^^^^^^^^^^
  File "/home/gbemike/Documents/github/nba_pipeline/.venv/lib/python3.11/site-packages/pandas/core/frame.py", line 4090, in __getitem__
    indexer = self.columns.get_loc(key)
              ^^^^^^^^^^^^^^^^^^^^^^^^^
  File "/home/gbemike/Documents/github/nba_pipeline/.venv/lib/python3.11/site-packages/pandas/core/indexes/base.py", line 3812, in get_loc
    raise KeyError(key) from err

The above exception was caused by the following exception:
KeyError: 'player_name'

Stack Trace:
  File "/home/gbemike/Documents/github/nba_pipeline/.venv/lib/python3.11/site-packages/pandas/core/indexes/base.py", line 3805, in get_loc
    return self._engine.get_loc(casted_key)
           ^^^^^^^^^^^^^^^^^^^^^^^^^^^^^^^^
  File "index.pyx", line 167, in pandas._libs.index.IndexEngine.get_loc
  File "index.pyx", line 196, in pandas._libs.index.IndexEngine.get_loc
  File "pandas/_libs/hashtable_class_helper.pxi", line 7081, in pandas._libs.hashtable.PyObjectHashTable.get_item
  File "pandas/_libs/hashtable_class_helper.pxi", line 7089, in pandas._libs.hashtable.PyObjectHashTable.get_item
[0m
